{
  "comments": [
    {
      "unresolved": true,
      "key": {
        "uuid": "7d08efc3_7a65df63",
        "filename": "tools/power-utils/version.cpp",
        "patchSetId": 1
      },
      "lineNbr": 25,
      "author": {
        "id": 1000331
      },
      "writtenOn": "2024-08-21T14:38:21Z",
      "side": 1,
      "message": "Since you are using std::runtime_error, you need to #include \u003cstdexcept\u003e.  If you take my suggestion below about improving checkFileExists(), you also need to #include \u003cexception\u003e",
      "revId": "eac70ad0bd17709272faa3f2da05120c8f755e9a",
      "serverId": "adbd0a64-1f21-4d83-b585-671fe73cb6e4"
    },
    {
      "unresolved": true,
      "key": {
        "uuid": "f886c8f7_2883ac9b",
        "filename": "tools/power-utils/version.cpp",
        "patchSetId": 1
      },
      "lineNbr": 229,
      "author": {
        "id": 1000331
      },
      "writtenOn": "2024-08-21T14:38:21Z",
      "side": 1,
      "message": "It would be helpful to know what the path was (since this is a util function) and why it failed.  It would help diagnose the problem.\n\nSo I\u0027d suggest something like:\n\n```\ncatch (const std::exception\u0026 e)\n{\n    log\u003clevel::ERR\u003e(\n       std::format(\"Unable to check for existence of {}: {}\", filePath, e.what()).c_str());\n}\n```",
      "range": {
        "startLine": 226,
        "startChar": 4,
        "endLine": 229,
        "endChar": 5
      },
      "revId": "eac70ad0bd17709272faa3f2da05120c8f755e9a",
      "serverId": "adbd0a64-1f21-4d83-b585-671fe73cb6e4"
    },
    {
      "unresolved": true,
      "key": {
        "uuid": "bbacf63c_1becb5a3",
        "filename": "tools/power-utils/version.cpp",
        "patchSetId": 1
      },
      "lineNbr": 285,
      "author": {
        "id": 1000331
      },
      "writtenOn": "2024-08-21T14:38:21Z",
      "side": 1,
      "message": "I\u0027m not sure you need this.  runtime_error is a child class of exception, so the following catch clause will catch it.  The exception details (e.what()) should indicate what type of error it was.  So I think you can delete this catch clause.",
      "range": {
        "startLine": 281,
        "startChar": 4,
        "endLine": 285,
        "endChar": 5
      },
      "revId": "eac70ad0bd17709272faa3f2da05120c8f755e9a",
      "serverId": "adbd0a64-1f21-4d83-b585-671fe73cb6e4"
    },
    {
      "unresolved": true,
      "key": {
        "uuid": "085012ae_2add5db2",
        "filename": "tools/power-utils/version.cpp",
        "patchSetId": 1
      },
      "lineNbr": 289,
      "author": {
        "id": 1000331
      },
      "writtenOn": "2024-08-21T14:38:21Z",
      "side": 1,
      "message": "Nit: On line 273 you return \"\".  Might want to do the same thing in both places because I was trying to determine for a minute whether it was an intentional difference.  return {} is probably a bit more efficient, but return \"\" is very clear.",
      "range": {
        "startLine": 289,
        "startChar": 15,
        "endLine": 289,
        "endChar": 17
      },
      "revId": "eac70ad0bd17709272faa3f2da05120c8f755e9a",
      "serverId": "adbd0a64-1f21-4d83-b585-671fe73cb6e4"
    }
  ]
}